2024-01-14 16:26:35,526 Getting artifact
[34m[1mwandb[39m[22m: [32m[41mERROR[39m[49m artifacts must be specified as 'collection:alias' (Error 400: Bad Request)
Traceback (most recent call last):
  File "/Users/ruilu/anaconda3/lib/python3.11/site-packages/wandb/apis/normalize.py", line 41, in wrapper
    return func(*args, **kwargs)
           ^^^^^^^^^^^^^^^^^^^^^
  File "/Users/ruilu/anaconda3/lib/python3.11/site-packages/wandb/apis/public/api.py", line 950, in artifact
    artifact = wandb.Artifact._from_name(
               ^^^^^^^^^^^^^^^^^^^^^^^^^^
  File "/Users/ruilu/anaconda3/lib/python3.11/site-packages/wandb/sdk/artifacts/artifact.py", line 248, in _from_name
    response = client.execute(
               ^^^^^^^^^^^^^^^
  File "/Users/ruilu/anaconda3/lib/python3.11/site-packages/wandb/sdk/lib/retry.py", line 212, in wrapped_fn
    return retrier(*args, **kargs)
           ^^^^^^^^^^^^^^^^^^^^^^^
  File "/Users/ruilu/anaconda3/lib/python3.11/site-packages/wandb/sdk/lib/retry.py", line 131, in __call__
    result = self._call_fn(*args, **kwargs)
             ^^^^^^^^^^^^^^^^^^^^^^^^^^^^^^
  File "/Users/ruilu/anaconda3/lib/python3.11/site-packages/wandb/apis/public/api.py", line 73, in execute
    return self._client.execute(*args, **kwargs)
           ^^^^^^^^^^^^^^^^^^^^^^^^^^^^^^^^^^^^^
  File "/Users/ruilu/anaconda3/lib/python3.11/site-packages/wandb/vendor/gql-0.2.0/wandb_gql/client.py", line 52, in execute
    result = self._get_result(document, *args, **kwargs)
             ^^^^^^^^^^^^^^^^^^^^^^^^^^^^^^^^^^^^^^^^^^^
  File "/Users/ruilu/anaconda3/lib/python3.11/site-packages/wandb/vendor/gql-0.2.0/wandb_gql/client.py", line 60, in _get_result
    return self.transport.execute(document, *args, **kwargs)
           ^^^^^^^^^^^^^^^^^^^^^^^^^^^^^^^^^^^^^^^^^^^^^^^^^
  File "/Users/ruilu/anaconda3/lib/python3.11/site-packages/wandb/sdk/lib/gql_request.py", line 59, in execute
    request.raise_for_status()
  File "/Users/ruilu/anaconda3/lib/python3.11/site-packages/requests/models.py", line 1021, in raise_for_status
    raise HTTPError(http_error_msg, response=self)
requests.exceptions.HTTPError: 400 Client Error: Bad Request for url: https://api.wandb.ai/graphql
During handling of the above exception, another exception occurred:
Traceback (most recent call last):
  File "/Users/ruilu/udacity_repo/use_artifact.py", line 41, in <module>
    go(args)
  File "/Users/ruilu/udacity_repo/use_artifact.py", line 18, in go
    artifact = run.use_artifact(args.artifact_name)
               ^^^^^^^^^^^^^^^^^^^^^^^^^^^^^^^^^^^^
  File "/Users/ruilu/anaconda3/lib/python3.11/site-packages/wandb/sdk/wandb_run.py", line 371, in wrapper_fn
    return func(self, *args, **kwargs)
           ^^^^^^^^^^^^^^^^^^^^^^^^^^^
  File "/Users/ruilu/anaconda3/lib/python3.11/site-packages/wandb/sdk/wandb_run.py", line 361, in wrapper
    return func(self, *args, **kwargs)
           ^^^^^^^^^^^^^^^^^^^^^^^^^^^
  File "/Users/ruilu/anaconda3/lib/python3.11/site-packages/wandb/sdk/wandb_run.py", line 2787, in use_artifact
    artifact = public_api.artifact(type=type, name=name)
               ^^^^^^^^^^^^^^^^^^^^^^^^^^^^^^^^^^^^^^^^^
  File "/Users/ruilu/anaconda3/lib/python3.11/site-packages/wandb/apis/normalize.py", line 51, in wrapper
    raise CommError(message, error)
wandb.errors.CommError: artifacts must be specified as 'collection:alias' (Error 400: Bad Request)